[2024-05-03T15:38:07.148+0000] {local_task_job_runner.py:120} INFO - ::group::Pre task execution logs
[2024-05-03T15:38:07.171+0000] {taskinstance.py:2073} INFO - Dependencies all met for dep_context=non-requeueable deps ti=<TaskInstance: accident_api_pipeline.upload_to_gcs manual__2024-04-21T14:19:28.470225+00:00 [queued]>
[2024-05-03T15:38:07.182+0000] {taskinstance.py:2073} INFO - Dependencies all met for dep_context=requeueable deps ti=<TaskInstance: accident_api_pipeline.upload_to_gcs manual__2024-04-21T14:19:28.470225+00:00 [queued]>
[2024-05-03T15:38:07.182+0000] {taskinstance.py:2303} INFO - Starting attempt 1 of 1
[2024-05-03T15:38:07.217+0000] {taskinstance.py:2327} INFO - Executing <Task(LocalFilesystemToGCSOperator): upload_to_gcs> on 2024-04-21 14:19:28.470225+00:00
[2024-05-03T15:38:07.239+0000] {warnings.py:110} WARNING - /home/***/.local/lib/python3.12/site-packages/***/task/task_runner/standard_task_runner.py:61: DeprecationWarning: This process (pid=104) is multi-threaded, use of fork() may lead to deadlocks in the child.
  pid = os.fork()

[2024-05-03T15:38:07.240+0000] {standard_task_runner.py:63} INFO - Started process 108 to run task
[2024-05-03T15:38:07.244+0000] {standard_task_runner.py:90} INFO - Running: ['***', 'tasks', 'run', 'accident_api_pipeline', 'upload_to_gcs', 'manual__2024-04-21T14:19:28.470225+00:00', '--job-id', '11', '--raw', '--subdir', 'DAGS_FOLDER/accident_api_pipeline.py', '--cfg-path', '/tmp/tmpm7uuty2n']
[2024-05-03T15:38:07.251+0000] {standard_task_runner.py:91} INFO - Job 11: Subtask upload_to_gcs
[2024-05-03T15:38:07.343+0000] {task_command.py:426} INFO - Running <TaskInstance: accident_api_pipeline.upload_to_gcs manual__2024-04-21T14:19:28.470225+00:00 [running]> on host d870bb3b2378
[2024-05-03T15:38:07.636+0000] {taskinstance.py:2644} INFO - Exporting env vars: AIRFLOW_CTX_DAG_OWNER='***' AIRFLOW_CTX_DAG_ID='accident_api_pipeline' AIRFLOW_CTX_TASK_ID='upload_to_gcs' AIRFLOW_CTX_EXECUTION_DATE='2024-04-21T14:19:28.470225+00:00' AIRFLOW_CTX_TRY_NUMBER='1' AIRFLOW_CTX_DAG_RUN_ID='manual__2024-04-21T14:19:28.470225+00:00'
[2024-05-03T15:38:07.642+0000] {taskinstance.py:430} INFO - ::endgroup::
[2024-05-03T15:38:07.678+0000] {connection.py:274} WARNING - Connection schemes (type: google_cloud_platform) shall not contain '_' according to RFC3986.
[2024-05-03T15:38:07.679+0000] {base.py:84} INFO - Using connection ID 'my_gcp_conn' for task execution.
[2024-05-03T15:38:07.682+0000] {credentials_provider.py:353} INFO - Getting connection using `google.auth.default()` since no explicit credentials are provided.
[2024-05-03T15:38:07.688+0000] {_default.py:338} WARNING - Authentication failed using Compute Engine authentication due to unavailable metadata server.
[2024-05-03T15:38:07.688+0000] {taskinstance.py:441} INFO - ::group::Post task execution logs
[2024-05-03T15:38:07.688+0000] {taskinstance.py:2890} ERROR - Task failed with exception
Traceback (most recent call last):
  File "/home/airflow/.local/lib/python3.12/site-packages/airflow/models/taskinstance.py", line 465, in _execute_task
    result = _execute_callable(context=context, **execute_callable_kwargs)
             ^^^^^^^^^^^^^^^^^^^^^^^^^^^^^^^^^^^^^^^^^^^^^^^^^^^^^^^^^^^^^
  File "/home/airflow/.local/lib/python3.12/site-packages/airflow/models/taskinstance.py", line 432, in _execute_callable
    return execute_callable(context=context, **execute_callable_kwargs)
           ^^^^^^^^^^^^^^^^^^^^^^^^^^^^^^^^^^^^^^^^^^^^^^^^^^^^^^^^^^^^
  File "/home/airflow/.local/lib/python3.12/site-packages/airflow/models/baseoperator.py", line 400, in wrapper
    return func(self, *args, **kwargs)
           ^^^^^^^^^^^^^^^^^^^^^^^^^^^
  File "/home/airflow/.local/lib/python3.12/site-packages/airflow/providers/google/cloud/transfers/local_to_gcs.py", line 110, in execute
    hook.upload(
  File "/home/airflow/.local/lib/python3.12/site-packages/airflow/providers/google/cloud/hooks/gcs.py", line 525, in upload
    client = self.get_conn()
             ^^^^^^^^^^^^^^^
  File "/home/airflow/.local/lib/python3.12/site-packages/airflow/providers/google/cloud/hooks/gcs.py", line 168, in get_conn
    credentials=self.get_credentials(), client_info=CLIENT_INFO, project=self.project_id
                ^^^^^^^^^^^^^^^^^^^^^^
  File "/home/airflow/.local/lib/python3.12/site-packages/airflow/providers/google/common/hooks/base_google.py", line 307, in get_credentials
    credentials, _ = self.get_credentials_and_project_id()
                     ^^^^^^^^^^^^^^^^^^^^^^^^^^^^^^^^^^^^^
  File "/home/airflow/.local/lib/python3.12/site-packages/airflow/providers/google/common/hooks/base_google.py", line 284, in get_credentials_and_project_id
    credentials, project_id = get_credentials_and_project_id(
                              ^^^^^^^^^^^^^^^^^^^^^^^^^^^^^^^
  File "/home/airflow/.local/lib/python3.12/site-packages/airflow/providers/google/cloud/utils/credentials_provider.py", line 362, in get_credentials_and_project_id
    return _CredentialProvider(*args, **kwargs).get_credentials_and_project()
           ^^^^^^^^^^^^^^^^^^^^^^^^^^^^^^^^^^^^^^^^^^^^^^^^^^^^^^^^^^^^^^^^^^
  File "/home/airflow/.local/lib/python3.12/site-packages/airflow/providers/google/cloud/utils/credentials_provider.py", line 243, in get_credentials_and_project
    credentials, project_id = self._get_credentials_using_adc()
                              ^^^^^^^^^^^^^^^^^^^^^^^^^^^^^^^^^
  File "/home/airflow/.local/lib/python3.12/site-packages/airflow/providers/google/cloud/utils/credentials_provider.py", line 348, in _get_credentials_using_adc
    credentials, project_id = google.auth.default(scopes=self.scopes)
                              ^^^^^^^^^^^^^^^^^^^^^^^^^^^^^^^^^^^^^^^
  File "/home/airflow/.local/lib/python3.12/site-packages/google/auth/_default.py", line 691, in default
    raise exceptions.DefaultCredentialsError(_CLOUD_SDK_MISSING_CREDENTIALS)
google.auth.exceptions.DefaultCredentialsError: Your default credentials were not found. To set up Application Default Credentials, see https://cloud.google.com/docs/authentication/external/set-up-adc for more information.
[2024-05-03T15:38:07.712+0000] {taskinstance.py:1205} INFO - Marking task as FAILED. dag_id=accident_api_pipeline, task_id=upload_to_gcs, execution_date=20240421T141928, start_date=20240503T153807, end_date=20240503T153807
[2024-05-03T15:38:07.750+0000] {standard_task_runner.py:110} ERROR - Failed to execute job 11 for task upload_to_gcs (Your default credentials were not found. To set up Application Default Credentials, see https://cloud.google.com/docs/authentication/external/set-up-adc for more information.; 108)
[2024-05-03T15:38:07.802+0000] {local_task_job_runner.py:240} INFO - Task exited with return code 1
[2024-05-03T15:38:07.829+0000] {taskinstance.py:3482} INFO - 0 downstream tasks scheduled from follow-on schedule check
[2024-05-03T15:38:07.851+0000] {local_task_job_runner.py:222} INFO - ::endgroup::
